{"timestamp": "2025-08-11T17:25:43.893167Z", "level": "ERROR", "logger": "app", "message": "Exception on /api/v1/health [GET]", "module": "app", "function": "log_exception", "line": 1414, "process_id": 48709, "thread_id": 123145459494912, "exception": "Traceback (most recent call last):\n  File \"/Users/user/Documents/Development/open-source-tools/GST-Verification-API/venv/lib/python3.13/site-packages/flask/app.py\", line 2190, in wsgi_app\n    response = self.full_dispatch_request()\n  File \"/Users/user/Documents/Development/open-source-tools/GST-Verification-API/venv/lib/python3.13/site-packages/flask/app.py\", line 1487, in full_dispatch_request\n    return self.finalize_request(rv)\n           ~~~~~~~~~~~~~~~~~~~~~^^^^\n  File \"/Users/user/Documents/Development/open-source-tools/GST-Verification-API/venv/lib/python3.13/site-packages/flask/app.py\", line 1508, in finalize_request\n    response = self.process_response(response)\n  File \"/Users/user/Documents/Development/open-source-tools/GST-Verification-API/venv/lib/python3.13/site-packages/flask/app.py\", line 2002, in process_response\n    response = self.ensure_sync(func)(response)\n  File \"/Users/user/Documents/Development/open-source-tools/GST-Verification-API/logging_config.py\", line 546, in after_request\n    duration = (datetime.utcnow() - g.start_time).total_seconds()\n                ~~~~~~~~~~~~~~~~~~^~~~~~~~~~~~~~\nTypeError: unsupported operand type(s) for -: 'datetime.datetime' and 'float'", "extra": {"taskName": null}}
{"timestamp": "2025-08-11T17:25:43.909929Z", "level": "ERROR", "logger": "gst_api", "message": "Internal server error: 500 Internal Server Error: The server encountered an internal error and was unable to complete your request. Either the server is overloaded or there is an error in the application.", "module": "app", "function": "internal_error", "line": 254, "process_id": 48709, "thread_id": 123145459494912, "exception": "Traceback (most recent call last):\n  File \"/Users/user/Documents/Development/open-source-tools/GST-Verification-API/venv/lib/python3.13/site-packages/flask/app.py\", line 2190, in wsgi_app\n    response = self.full_dispatch_request()\n  File \"/Users/user/Documents/Development/open-source-tools/GST-Verification-API/venv/lib/python3.13/site-packages/flask/app.py\", line 1487, in full_dispatch_request\n    return self.finalize_request(rv)\n           ~~~~~~~~~~~~~~~~~~~~~^^^^\n  File \"/Users/user/Documents/Development/open-source-tools/GST-Verification-API/venv/lib/python3.13/site-packages/flask/app.py\", line 1508, in finalize_request\n    response = self.process_response(response)\n  File \"/Users/user/Documents/Development/open-source-tools/GST-Verification-API/venv/lib/python3.13/site-packages/flask/app.py\", line 2002, in process_response\n    response = self.ensure_sync(func)(response)\n  File \"/Users/user/Documents/Development/open-source-tools/GST-Verification-API/logging_config.py\", line 546, in after_request\n    duration = (datetime.utcnow() - g.start_time).total_seconds()\n                ~~~~~~~~~~~~~~~~~~^~~~~~~~~~~~~~\nTypeError: unsupported operand type(s) for -: 'datetime.datetime' and 'float'", "extra": {"taskName": null, "request_id": "6ef44a05-2630-437d-8276-7bd65dfd83c0"}}
{"timestamp": "2025-08-11T17:25:43.915725Z", "level": "ERROR", "logger": "app", "message": "Request finalizing failed with an error while handling an error", "module": "app", "function": "finalize_request", "line": 1515, "process_id": 48709, "thread_id": 123145459494912, "exception": "Traceback (most recent call last):\n  File \"/Users/user/Documents/Development/open-source-tools/GST-Verification-API/venv/lib/python3.13/site-packages/flask/app.py\", line 2190, in wsgi_app\n    response = self.full_dispatch_request()\n  File \"/Users/user/Documents/Development/open-source-tools/GST-Verification-API/venv/lib/python3.13/site-packages/flask/app.py\", line 1487, in full_dispatch_request\n    return self.finalize_request(rv)\n           ~~~~~~~~~~~~~~~~~~~~~^^^^\n  File \"/Users/user/Documents/Development/open-source-tools/GST-Verification-API/venv/lib/python3.13/site-packages/flask/app.py\", line 1508, in finalize_request\n    response = self.process_response(response)\n  File \"/Users/user/Documents/Development/open-source-tools/GST-Verification-API/venv/lib/python3.13/site-packages/flask/app.py\", line 2002, in process_response\n    response = self.ensure_sync(func)(response)\n  File \"/Users/user/Documents/Development/open-source-tools/GST-Verification-API/logging_config.py\", line 546, in after_request\n    duration = (datetime.utcnow() - g.start_time).total_seconds()\n                ~~~~~~~~~~~~~~~~~~^~~~~~~~~~~~~~\nTypeError: unsupported operand type(s) for -: 'datetime.datetime' and 'float'\n\nDuring handling of the above exception, another exception occurred:\n\nTraceback (most recent call last):\n  File \"/Users/user/Documents/Development/open-source-tools/GST-Verification-API/venv/lib/python3.13/site-packages/flask/app.py\", line 1508, in finalize_request\n    response = self.process_response(response)\n  File \"/Users/user/Documents/Development/open-source-tools/GST-Verification-API/venv/lib/python3.13/site-packages/flask/app.py\", line 2002, in process_response\n    response = self.ensure_sync(func)(response)\n  File \"/Users/user/Documents/Development/open-source-tools/GST-Verification-API/logging_config.py\", line 546, in after_request\n    duration = (datetime.utcnow() - g.start_time).total_seconds()\n                ~~~~~~~~~~~~~~~~~~^~~~~~~~~~~~~~\nTypeError: unsupported operand type(s) for -: 'datetime.datetime' and 'float'", "extra": {"taskName": null}}
{"timestamp": "2025-08-11T17:25:43.956778Z", "level": "ERROR", "logger": "werkzeug", "message": "Error on request:\nTraceback (most recent call last):\n  File \"/Users/user/Documents/Development/open-source-tools/GST-Verification-API/venv/lib/python3.13/site-packages/werkzeug/serving.py\", line 364, in run_wsgi\n    execute(self.server.app)\n    ~~~~~~~^^^^^^^^^^^^^^^^^\n  File \"/Users/user/Documents/Development/open-source-tools/GST-Verification-API/venv/lib/python3.13/site-packages/werkzeug/serving.py\", line 325, in execute\n    application_iter = app(environ, start_response)\n  File \"/Users/user/Documents/Development/open-source-tools/GST-Verification-API/venv/lib/python3.13/site-packages/flask/app.py\", line 2213, in __call__\n    return self.wsgi_app(environ, start_response)\n           ~~~~~~~~~~~~~^^^^^^^^^^^^^^^^^^^^^^^^^\n  File \"/Users/user/Documents/Development/open-source-tools/GST-Verification-API/venv/lib/python3.13/site-packages/flask/app.py\", line 2206, in wsgi_app\n    ctx.pop(error)\n    ~~~~~~~^^^^^^^\n  File \"/Users/user/Documents/Development/open-source-tools/GST-Verification-API/venv/lib/python3.13/site-packages/flask/ctx.py\", line 401, in pop\n    self.app.do_teardown_request(exc)\n    ~~~~~~~~~~~~~~~~~~~~~~~~~~~~^^^^^\n  File \"/Users/user/Documents/Development/open-source-tools/GST-Verification-API/venv/lib/python3.13/site-packages/flask/app.py\", line 2038, in do_teardown_request\n    self.ensure_sync(func)(exc)\n    ~~~~~~~~~~~~~~~~~~~~~~^^^^^\n  File \"/Users/user/Documents/Development/open-source-tools/GST-Verification-API/logging_config.py\", line 567, in teardown_request\n    'request_path': getattr(request, 'path', 'unknown'),\n                            ^^^^^^^\nNameError: name 'request' is not defined", "module": "_internal", "function": "_log", "line": 187, "process_id": 48709, "thread_id": 123145459494912, "extra": {"taskName": null}}
{"timestamp": "2025-08-11T17:25:51.594293Z", "level": "ERROR", "logger": "gst_api", "message": "Health check failed: 'HealthChecker' object has no attribute 'check_health'", "module": "app", "function": "health_check", "line": 541, "process_id": 48709, "thread_id": 123145476284416, "extra": {"taskName": null}}
{"timestamp": "2025-08-11T17:25:51.595913Z", "level": "ERROR", "logger": "app", "message": "Exception on /health [GET]", "module": "app", "function": "log_exception", "line": 1414, "process_id": 48709, "thread_id": 123145476284416, "exception": "Traceback (most recent call last):\n  File \"/Users/user/Documents/Development/open-source-tools/GST-Verification-API/venv/lib/python3.13/site-packages/flask/app.py\", line 2190, in wsgi_app\n    response = self.full_dispatch_request()\n  File \"/Users/user/Documents/Development/open-source-tools/GST-Verification-API/venv/lib/python3.13/site-packages/flask/app.py\", line 1487, in full_dispatch_request\n    return self.finalize_request(rv)\n           ~~~~~~~~~~~~~~~~~~~~~^^^^\n  File \"/Users/user/Documents/Development/open-source-tools/GST-Verification-API/venv/lib/python3.13/site-packages/flask/app.py\", line 1508, in finalize_request\n    response = self.process_response(response)\n  File \"/Users/user/Documents/Development/open-source-tools/GST-Verification-API/venv/lib/python3.13/site-packages/flask/app.py\", line 2002, in process_response\n    response = self.ensure_sync(func)(response)\n  File \"/Users/user/Documents/Development/open-source-tools/GST-Verification-API/logging_config.py\", line 546, in after_request\n    duration = (datetime.utcnow() - g.start_time).total_seconds()\n                ~~~~~~~~~~~~~~~~~~^~~~~~~~~~~~~~\nTypeError: unsupported operand type(s) for -: 'datetime.datetime' and 'float'", "extra": {"taskName": null}}
{"timestamp": "2025-08-11T17:25:51.600167Z", "level": "ERROR", "logger": "gst_api", "message": "Internal server error: 500 Internal Server Error: The server encountered an internal error and was unable to complete your request. Either the server is overloaded or there is an error in the application.", "module": "app", "function": "internal_error", "line": 254, "process_id": 48709, "thread_id": 123145476284416, "exception": "Traceback (most recent call last):\n  File \"/Users/user/Documents/Development/open-source-tools/GST-Verification-API/venv/lib/python3.13/site-packages/flask/app.py\", line 2190, in wsgi_app\n    response = self.full_dispatch_request()\n  File \"/Users/user/Documents/Development/open-source-tools/GST-Verification-API/venv/lib/python3.13/site-packages/flask/app.py\", line 1487, in full_dispatch_request\n    return self.finalize_request(rv)\n           ~~~~~~~~~~~~~~~~~~~~~^^^^\n  File \"/Users/user/Documents/Development/open-source-tools/GST-Verification-API/venv/lib/python3.13/site-packages/flask/app.py\", line 1508, in finalize_request\n    response = self.process_response(response)\n  File \"/Users/user/Documents/Development/open-source-tools/GST-Verification-API/venv/lib/python3.13/site-packages/flask/app.py\", line 2002, in process_response\n    response = self.ensure_sync(func)(response)\n  File \"/Users/user/Documents/Development/open-source-tools/GST-Verification-API/logging_config.py\", line 546, in after_request\n    duration = (datetime.utcnow() - g.start_time).total_seconds()\n                ~~~~~~~~~~~~~~~~~~^~~~~~~~~~~~~~\nTypeError: unsupported operand type(s) for -: 'datetime.datetime' and 'float'", "extra": {"taskName": null, "request_id": "33ec1743-a310-4976-ab3c-604473875e2e"}}
{"timestamp": "2025-08-11T17:25:51.604035Z", "level": "ERROR", "logger": "app", "message": "Request finalizing failed with an error while handling an error", "module": "app", "function": "finalize_request", "line": 1515, "process_id": 48709, "thread_id": 123145476284416, "exception": "Traceback (most recent call last):\n  File \"/Users/user/Documents/Development/open-source-tools/GST-Verification-API/venv/lib/python3.13/site-packages/flask/app.py\", line 2190, in wsgi_app\n    response = self.full_dispatch_request()\n  File \"/Users/user/Documents/Development/open-source-tools/GST-Verification-API/venv/lib/python3.13/site-packages/flask/app.py\", line 1487, in full_dispatch_request\n    return self.finalize_request(rv)\n           ~~~~~~~~~~~~~~~~~~~~~^^^^\n  File \"/Users/user/Documents/Development/open-source-tools/GST-Verification-API/venv/lib/python3.13/site-packages/flask/app.py\", line 1508, in finalize_request\n    response = self.process_response(response)\n  File \"/Users/user/Documents/Development/open-source-tools/GST-Verification-API/venv/lib/python3.13/site-packages/flask/app.py\", line 2002, in process_response\n    response = self.ensure_sync(func)(response)\n  File \"/Users/user/Documents/Development/open-source-tools/GST-Verification-API/logging_config.py\", line 546, in after_request\n    duration = (datetime.utcnow() - g.start_time).total_seconds()\n                ~~~~~~~~~~~~~~~~~~^~~~~~~~~~~~~~\nTypeError: unsupported operand type(s) for -: 'datetime.datetime' and 'float'\n\nDuring handling of the above exception, another exception occurred:\n\nTraceback (most recent call last):\n  File \"/Users/user/Documents/Development/open-source-tools/GST-Verification-API/venv/lib/python3.13/site-packages/flask/app.py\", line 1508, in finalize_request\n    response = self.process_response(response)\n  File \"/Users/user/Documents/Development/open-source-tools/GST-Verification-API/venv/lib/python3.13/site-packages/flask/app.py\", line 2002, in process_response\n    response = self.ensure_sync(func)(response)\n  File \"/Users/user/Documents/Development/open-source-tools/GST-Verification-API/logging_config.py\", line 546, in after_request\n    duration = (datetime.utcnow() - g.start_time).total_seconds()\n                ~~~~~~~~~~~~~~~~~~^~~~~~~~~~~~~~\nTypeError: unsupported operand type(s) for -: 'datetime.datetime' and 'float'", "extra": {"taskName": null}}
{"timestamp": "2025-08-11T17:25:51.612763Z", "level": "ERROR", "logger": "werkzeug", "message": "Error on request:\nTraceback (most recent call last):\n  File \"/Users/user/Documents/Development/open-source-tools/GST-Verification-API/venv/lib/python3.13/site-packages/werkzeug/serving.py\", line 364, in run_wsgi\n    execute(self.server.app)\n    ~~~~~~~^^^^^^^^^^^^^^^^^\n  File \"/Users/user/Documents/Development/open-source-tools/GST-Verification-API/venv/lib/python3.13/site-packages/werkzeug/serving.py\", line 325, in execute\n    application_iter = app(environ, start_response)\n  File \"/Users/user/Documents/Development/open-source-tools/GST-Verification-API/venv/lib/python3.13/site-packages/flask/app.py\", line 2213, in __call__\n    return self.wsgi_app(environ, start_response)\n           ~~~~~~~~~~~~~^^^^^^^^^^^^^^^^^^^^^^^^^\n  File \"/Users/user/Documents/Development/open-source-tools/GST-Verification-API/venv/lib/python3.13/site-packages/flask/app.py\", line 2206, in wsgi_app\n    ctx.pop(error)\n    ~~~~~~~^^^^^^^\n  File \"/Users/user/Documents/Development/open-source-tools/GST-Verification-API/venv/lib/python3.13/site-packages/flask/ctx.py\", line 401, in pop\n    self.app.do_teardown_request(exc)\n    ~~~~~~~~~~~~~~~~~~~~~~~~~~~~^^^^^\n  File \"/Users/user/Documents/Development/open-source-tools/GST-Verification-API/venv/lib/python3.13/site-packages/flask/app.py\", line 2038, in do_teardown_request\n    self.ensure_sync(func)(exc)\n    ~~~~~~~~~~~~~~~~~~~~~~^^^^^\n  File \"/Users/user/Documents/Development/open-source-tools/GST-Verification-API/logging_config.py\", line 567, in teardown_request\n    'request_path': getattr(request, 'path', 'unknown'),\n                            ^^^^^^^\nNameError: name 'request' is not defined", "module": "_internal", "function": "_log", "line": 187, "process_id": 48709, "thread_id": 123145476284416, "extra": {"taskName": null}}
{"timestamp": "2025-08-11T17:26:35.299277Z", "level": "ERROR", "logger": "gst_api", "message": "Health check failed: 'HealthChecker' object has no attribute 'check_health'", "module": "app", "function": "health_check", "line": 541, "process_id": 50105, "thread_id": 123145602699264, "extra": {"taskName": null}}
{"timestamp": "2025-08-11T17:26:35.300576Z", "level": "ERROR", "logger": "app", "message": "Exception on /health [GET]", "module": "app", "function": "log_exception", "line": 1414, "process_id": 50105, "thread_id": 123145602699264, "exception": "Traceback (most recent call last):\n  File \"/Users/user/Documents/Development/open-source-tools/GST-Verification-API/venv/lib/python3.13/site-packages/flask/app.py\", line 2190, in wsgi_app\n    response = self.full_dispatch_request()\n  File \"/Users/user/Documents/Development/open-source-tools/GST-Verification-API/venv/lib/python3.13/site-packages/flask/app.py\", line 1487, in full_dispatch_request\n    return self.finalize_request(rv)\n           ~~~~~~~~~~~~~~~~~~~~~^^^^\n  File \"/Users/user/Documents/Development/open-source-tools/GST-Verification-API/venv/lib/python3.13/site-packages/flask/app.py\", line 1508, in finalize_request\n    response = self.process_response(response)\n  File \"/Users/user/Documents/Development/open-source-tools/GST-Verification-API/venv/lib/python3.13/site-packages/flask/app.py\", line 2002, in process_response\n    response = self.ensure_sync(func)(response)\n  File \"/Users/user/Documents/Development/open-source-tools/GST-Verification-API/logging_config.py\", line 546, in after_request\n    duration = (datetime.utcnow() - g.start_time).total_seconds()\n                ~~~~~~~~~~~~~~~~~~^~~~~~~~~~~~~~\nTypeError: unsupported operand type(s) for -: 'datetime.datetime' and 'float'", "extra": {"taskName": null}}
{"timestamp": "2025-08-11T17:26:35.310970Z", "level": "ERROR", "logger": "gst_api", "message": "Internal server error: 500 Internal Server Error: The server encountered an internal error and was unable to complete your request. Either the server is overloaded or there is an error in the application.", "module": "app", "function": "internal_error", "line": 254, "process_id": 50105, "thread_id": 123145602699264, "exception": "Traceback (most recent call last):\n  File \"/Users/user/Documents/Development/open-source-tools/GST-Verification-API/venv/lib/python3.13/site-packages/flask/app.py\", line 2190, in wsgi_app\n    response = self.full_dispatch_request()\n  File \"/Users/user/Documents/Development/open-source-tools/GST-Verification-API/venv/lib/python3.13/site-packages/flask/app.py\", line 1487, in full_dispatch_request\n    return self.finalize_request(rv)\n           ~~~~~~~~~~~~~~~~~~~~~^^^^\n  File \"/Users/user/Documents/Development/open-source-tools/GST-Verification-API/venv/lib/python3.13/site-packages/flask/app.py\", line 1508, in finalize_request\n    response = self.process_response(response)\n  File \"/Users/user/Documents/Development/open-source-tools/GST-Verification-API/venv/lib/python3.13/site-packages/flask/app.py\", line 2002, in process_response\n    response = self.ensure_sync(func)(response)\n  File \"/Users/user/Documents/Development/open-source-tools/GST-Verification-API/logging_config.py\", line 546, in after_request\n    duration = (datetime.utcnow() - g.start_time).total_seconds()\n                ~~~~~~~~~~~~~~~~~~^~~~~~~~~~~~~~\nTypeError: unsupported operand type(s) for -: 'datetime.datetime' and 'float'", "extra": {"taskName": null, "request_id": "38654aa4-379f-40c4-8488-77b1c00fe76f"}}
{"timestamp": "2025-08-11T17:26:35.318103Z", "level": "ERROR", "logger": "app", "message": "Request finalizing failed with an error while handling an error", "module": "app", "function": "finalize_request", "line": 1515, "process_id": 50105, "thread_id": 123145602699264, "exception": "Traceback (most recent call last):\n  File \"/Users/user/Documents/Development/open-source-tools/GST-Verification-API/venv/lib/python3.13/site-packages/flask/app.py\", line 2190, in wsgi_app\n    response = self.full_dispatch_request()\n  File \"/Users/user/Documents/Development/open-source-tools/GST-Verification-API/venv/lib/python3.13/site-packages/flask/app.py\", line 1487, in full_dispatch_request\n    return self.finalize_request(rv)\n           ~~~~~~~~~~~~~~~~~~~~~^^^^\n  File \"/Users/user/Documents/Development/open-source-tools/GST-Verification-API/venv/lib/python3.13/site-packages/flask/app.py\", line 1508, in finalize_request\n    response = self.process_response(response)\n  File \"/Users/user/Documents/Development/open-source-tools/GST-Verification-API/venv/lib/python3.13/site-packages/flask/app.py\", line 2002, in process_response\n    response = self.ensure_sync(func)(response)\n  File \"/Users/user/Documents/Development/open-source-tools/GST-Verification-API/logging_config.py\", line 546, in after_request\n    duration = (datetime.utcnow() - g.start_time).total_seconds()\n                ~~~~~~~~~~~~~~~~~~^~~~~~~~~~~~~~\nTypeError: unsupported operand type(s) for -: 'datetime.datetime' and 'float'\n\nDuring handling of the above exception, another exception occurred:\n\nTraceback (most recent call last):\n  File \"/Users/user/Documents/Development/open-source-tools/GST-Verification-API/venv/lib/python3.13/site-packages/flask/app.py\", line 1508, in finalize_request\n    response = self.process_response(response)\n  File \"/Users/user/Documents/Development/open-source-tools/GST-Verification-API/venv/lib/python3.13/site-packages/flask/app.py\", line 2002, in process_response\n    response = self.ensure_sync(func)(response)\n  File \"/Users/user/Documents/Development/open-source-tools/GST-Verification-API/logging_config.py\", line 546, in after_request\n    duration = (datetime.utcnow() - g.start_time).total_seconds()\n                ~~~~~~~~~~~~~~~~~~^~~~~~~~~~~~~~\nTypeError: unsupported operand type(s) for -: 'datetime.datetime' and 'float'", "extra": {"taskName": null}}
{"timestamp": "2025-08-11T17:26:35.328046Z", "level": "ERROR", "logger": "gst_api.errors", "message": "Request failed with exception: unsupported operand type(s) for -: 'datetime.datetime' and 'float'", "module": "logging_config", "function": "teardown_request", "line": 563, "process_id": 50105, "thread_id": 123145602699264, "exception": "NoneType: None", "extra": {"taskName": null, "exception_type": "TypeError", "request_path": "/health", "request_method": "GET"}}
{"timestamp": "2025-08-11T17:26:43.359089Z", "level": "ERROR", "logger": "app", "message": "Exception on / [GET]", "module": "app", "function": "log_exception", "line": 1414, "process_id": 50105, "thread_id": 123145619488768, "exception": "Traceback (most recent call last):\n  File \"/Users/user/Documents/Development/open-source-tools/GST-Verification-API/venv/lib/python3.13/site-packages/flask/app.py\", line 2190, in wsgi_app\n    response = self.full_dispatch_request()\n  File \"/Users/user/Documents/Development/open-source-tools/GST-Verification-API/venv/lib/python3.13/site-packages/flask/app.py\", line 1487, in full_dispatch_request\n    return self.finalize_request(rv)\n           ~~~~~~~~~~~~~~~~~~~~~^^^^\n  File \"/Users/user/Documents/Development/open-source-tools/GST-Verification-API/venv/lib/python3.13/site-packages/flask/app.py\", line 1508, in finalize_request\n    response = self.process_response(response)\n  File \"/Users/user/Documents/Development/open-source-tools/GST-Verification-API/venv/lib/python3.13/site-packages/flask/app.py\", line 2002, in process_response\n    response = self.ensure_sync(func)(response)\n  File \"/Users/user/Documents/Development/open-source-tools/GST-Verification-API/logging_config.py\", line 546, in after_request\n    duration = (datetime.utcnow() - g.start_time).total_seconds()\n                ~~~~~~~~~~~~~~~~~~^~~~~~~~~~~~~~\nTypeError: unsupported operand type(s) for -: 'datetime.datetime' and 'float'", "extra": {"taskName": null}}
{"timestamp": "2025-08-11T17:26:43.362645Z", "level": "ERROR", "logger": "gst_api", "message": "Internal server error: 500 Internal Server Error: The server encountered an internal error and was unable to complete your request. Either the server is overloaded or there is an error in the application.", "module": "app", "function": "internal_error", "line": 254, "process_id": 50105, "thread_id": 123145619488768, "exception": "Traceback (most recent call last):\n  File \"/Users/user/Documents/Development/open-source-tools/GST-Verification-API/venv/lib/python3.13/site-packages/flask/app.py\", line 2190, in wsgi_app\n    response = self.full_dispatch_request()\n  File \"/Users/user/Documents/Development/open-source-tools/GST-Verification-API/venv/lib/python3.13/site-packages/flask/app.py\", line 1487, in full_dispatch_request\n    return self.finalize_request(rv)\n           ~~~~~~~~~~~~~~~~~~~~~^^^^\n  File \"/Users/user/Documents/Development/open-source-tools/GST-Verification-API/venv/lib/python3.13/site-packages/flask/app.py\", line 1508, in finalize_request\n    response = self.process_response(response)\n  File \"/Users/user/Documents/Development/open-source-tools/GST-Verification-API/venv/lib/python3.13/site-packages/flask/app.py\", line 2002, in process_response\n    response = self.ensure_sync(func)(response)\n  File \"/Users/user/Documents/Development/open-source-tools/GST-Verification-API/logging_config.py\", line 546, in after_request\n    duration = (datetime.utcnow() - g.start_time).total_seconds()\n                ~~~~~~~~~~~~~~~~~~^~~~~~~~~~~~~~\nTypeError: unsupported operand type(s) for -: 'datetime.datetime' and 'float'", "extra": {"taskName": null, "request_id": "b61dc6e9-486c-4c36-ab2e-3822d860cf50"}}
{"timestamp": "2025-08-11T17:26:43.365772Z", "level": "ERROR", "logger": "app", "message": "Request finalizing failed with an error while handling an error", "module": "app", "function": "finalize_request", "line": 1515, "process_id": 50105, "thread_id": 123145619488768, "exception": "Traceback (most recent call last):\n  File \"/Users/user/Documents/Development/open-source-tools/GST-Verification-API/venv/lib/python3.13/site-packages/flask/app.py\", line 2190, in wsgi_app\n    response = self.full_dispatch_request()\n  File \"/Users/user/Documents/Development/open-source-tools/GST-Verification-API/venv/lib/python3.13/site-packages/flask/app.py\", line 1487, in full_dispatch_request\n    return self.finalize_request(rv)\n           ~~~~~~~~~~~~~~~~~~~~~^^^^\n  File \"/Users/user/Documents/Development/open-source-tools/GST-Verification-API/venv/lib/python3.13/site-packages/flask/app.py\", line 1508, in finalize_request\n    response = self.process_response(response)\n  File \"/Users/user/Documents/Development/open-source-tools/GST-Verification-API/venv/lib/python3.13/site-packages/flask/app.py\", line 2002, in process_response\n    response = self.ensure_sync(func)(response)\n  File \"/Users/user/Documents/Development/open-source-tools/GST-Verification-API/logging_config.py\", line 546, in after_request\n    duration = (datetime.utcnow() - g.start_time).total_seconds()\n                ~~~~~~~~~~~~~~~~~~^~~~~~~~~~~~~~\nTypeError: unsupported operand type(s) for -: 'datetime.datetime' and 'float'\n\nDuring handling of the above exception, another exception occurred:\n\nTraceback (most recent call last):\n  File \"/Users/user/Documents/Development/open-source-tools/GST-Verification-API/venv/lib/python3.13/site-packages/flask/app.py\", line 1508, in finalize_request\n    response = self.process_response(response)\n  File \"/Users/user/Documents/Development/open-source-tools/GST-Verification-API/venv/lib/python3.13/site-packages/flask/app.py\", line 2002, in process_response\n    response = self.ensure_sync(func)(response)\n  File \"/Users/user/Documents/Development/open-source-tools/GST-Verification-API/logging_config.py\", line 546, in after_request\n    duration = (datetime.utcnow() - g.start_time).total_seconds()\n                ~~~~~~~~~~~~~~~~~~^~~~~~~~~~~~~~\nTypeError: unsupported operand type(s) for -: 'datetime.datetime' and 'float'", "extra": {"taskName": null}}
{"timestamp": "2025-08-11T17:26:43.371579Z", "level": "ERROR", "logger": "gst_api.errors", "message": "Request failed with exception: unsupported operand type(s) for -: 'datetime.datetime' and 'float'", "module": "logging_config", "function": "teardown_request", "line": 563, "process_id": 50105, "thread_id": 123145619488768, "exception": "NoneType: None", "extra": {"taskName": null, "exception_type": "TypeError", "request_path": "/", "request_method": "GET"}}
{"timestamp": "2025-08-11T17:28:45.663327Z", "level": "ERROR", "logger": "app", "message": "Exception on /captcha [GET]", "module": "app", "function": "log_exception", "line": 1414, "process_id": 50105, "thread_id": 123145636278272, "exception": "Traceback (most recent call last):\n  File \"/Users/user/Documents/Development/open-source-tools/GST-Verification-API/venv/lib/python3.13/site-packages/flask/app.py\", line 2190, in wsgi_app\n    response = self.full_dispatch_request()\n  File \"/Users/user/Documents/Development/open-source-tools/GST-Verification-API/venv/lib/python3.13/site-packages/flask/app.py\", line 1487, in full_dispatch_request\n    return self.finalize_request(rv)\n           ~~~~~~~~~~~~~~~~~~~~~^^^^\n  File \"/Users/user/Documents/Development/open-source-tools/GST-Verification-API/venv/lib/python3.13/site-packages/flask/app.py\", line 1508, in finalize_request\n    response = self.process_response(response)\n  File \"/Users/user/Documents/Development/open-source-tools/GST-Verification-API/venv/lib/python3.13/site-packages/flask/app.py\", line 2002, in process_response\n    response = self.ensure_sync(func)(response)\n  File \"/Users/user/Documents/Development/open-source-tools/GST-Verification-API/logging_config.py\", line 546, in after_request\nTypeError: unsupported operand type(s) for -: 'datetime.datetime' and 'float'", "extra": {"taskName": null}}
{"timestamp": "2025-08-11T17:28:45.667384Z", "level": "ERROR", "logger": "gst_api", "message": "Internal server error: 500 Internal Server Error: The server encountered an internal error and was unable to complete your request. Either the server is overloaded or there is an error in the application.", "module": "app", "function": "internal_error", "line": 254, "process_id": 50105, "thread_id": 123145636278272, "exception": "Traceback (most recent call last):\n  File \"/Users/user/Documents/Development/open-source-tools/GST-Verification-API/venv/lib/python3.13/site-packages/flask/app.py\", line 2190, in wsgi_app\n    response = self.full_dispatch_request()\n  File \"/Users/user/Documents/Development/open-source-tools/GST-Verification-API/venv/lib/python3.13/site-packages/flask/app.py\", line 1487, in full_dispatch_request\n    return self.finalize_request(rv)\n           ~~~~~~~~~~~~~~~~~~~~~^^^^\n  File \"/Users/user/Documents/Development/open-source-tools/GST-Verification-API/venv/lib/python3.13/site-packages/flask/app.py\", line 1508, in finalize_request\n    response = self.process_response(response)\n  File \"/Users/user/Documents/Development/open-source-tools/GST-Verification-API/venv/lib/python3.13/site-packages/flask/app.py\", line 2002, in process_response\n    response = self.ensure_sync(func)(response)\n  File \"/Users/user/Documents/Development/open-source-tools/GST-Verification-API/logging_config.py\", line 546, in after_request\nTypeError: unsupported operand type(s) for -: 'datetime.datetime' and 'float'", "extra": {"taskName": null, "request_id": "8ff007a9-a91b-4f0f-8886-acaf744eb799"}}
{"timestamp": "2025-08-11T17:28:45.670365Z", "level": "ERROR", "logger": "app", "message": "Request finalizing failed with an error while handling an error", "module": "app", "function": "finalize_request", "line": 1515, "process_id": 50105, "thread_id": 123145636278272, "exception": "Traceback (most recent call last):\n  File \"/Users/user/Documents/Development/open-source-tools/GST-Verification-API/venv/lib/python3.13/site-packages/flask/app.py\", line 2190, in wsgi_app\n    response = self.full_dispatch_request()\n  File \"/Users/user/Documents/Development/open-source-tools/GST-Verification-API/venv/lib/python3.13/site-packages/flask/app.py\", line 1487, in full_dispatch_request\n    return self.finalize_request(rv)\n           ~~~~~~~~~~~~~~~~~~~~~^^^^\n  File \"/Users/user/Documents/Development/open-source-tools/GST-Verification-API/venv/lib/python3.13/site-packages/flask/app.py\", line 1508, in finalize_request\n    response = self.process_response(response)\n  File \"/Users/user/Documents/Development/open-source-tools/GST-Verification-API/venv/lib/python3.13/site-packages/flask/app.py\", line 2002, in process_response\n    response = self.ensure_sync(func)(response)\n  File \"/Users/user/Documents/Development/open-source-tools/GST-Verification-API/logging_config.py\", line 546, in after_request\nTypeError: unsupported operand type(s) for -: 'datetime.datetime' and 'float'\n\nDuring handling of the above exception, another exception occurred:\n\nTraceback (most recent call last):\n  File \"/Users/user/Documents/Development/open-source-tools/GST-Verification-API/venv/lib/python3.13/site-packages/flask/app.py\", line 1508, in finalize_request\n    response = self.process_response(response)\n  File \"/Users/user/Documents/Development/open-source-tools/GST-Verification-API/venv/lib/python3.13/site-packages/flask/app.py\", line 2002, in process_response\n    response = self.ensure_sync(func)(response)\n  File \"/Users/user/Documents/Development/open-source-tools/GST-Verification-API/logging_config.py\", line 546, in after_request\nTypeError: unsupported operand type(s) for -: 'datetime.datetime' and 'float'", "extra": {"taskName": null}}
{"timestamp": "2025-08-11T17:28:45.674032Z", "level": "ERROR", "logger": "gst_api.errors", "message": "Request failed with exception: unsupported operand type(s) for -: 'datetime.datetime' and 'float'", "module": "logging_config", "function": "teardown_request", "line": 563, "process_id": 50105, "thread_id": 123145636278272, "exception": "NoneType: None", "extra": {"taskName": null, "exception_type": "TypeError", "request_path": "/captcha", "request_method": "GET"}}
{"timestamp": "2025-08-11T17:29:15.380294Z", "level": "ERROR", "logger": "app", "message": "Exception on /captcha [GET]", "module": "app", "function": "log_exception", "line": 1414, "process_id": 50105, "thread_id": 123145602699264, "exception": "Traceback (most recent call last):\n  File \"/Users/user/Documents/Development/open-source-tools/GST-Verification-API/venv/lib/python3.13/site-packages/flask/app.py\", line 2190, in wsgi_app\n    response = self.full_dispatch_request()\n  File \"/Users/user/Documents/Development/open-source-tools/GST-Verification-API/venv/lib/python3.13/site-packages/flask/app.py\", line 1487, in full_dispatch_request\n    return self.finalize_request(rv)\n           ~~~~~~~~~~~~~~~~~~~~~^^^^\n  File \"/Users/user/Documents/Development/open-source-tools/GST-Verification-API/venv/lib/python3.13/site-packages/flask/app.py\", line 1508, in finalize_request\n    response = self.process_response(response)\n  File \"/Users/user/Documents/Development/open-source-tools/GST-Verification-API/venv/lib/python3.13/site-packages/flask/app.py\", line 2002, in process_response\n    response = self.ensure_sync(func)(response)\n  File \"/Users/user/Documents/Development/open-source-tools/GST-Verification-API/logging_config.py\", line 546, in after_request\nTypeError: unsupported operand type(s) for -: 'datetime.datetime' and 'float'", "extra": {"taskName": null}}
{"timestamp": "2025-08-11T17:29:15.383230Z", "level": "ERROR", "logger": "gst_api", "message": "Internal server error: 500 Internal Server Error: The server encountered an internal error and was unable to complete your request. Either the server is overloaded or there is an error in the application.", "module": "app", "function": "internal_error", "line": 254, "process_id": 50105, "thread_id": 123145602699264, "exception": "Traceback (most recent call last):\n  File \"/Users/user/Documents/Development/open-source-tools/GST-Verification-API/venv/lib/python3.13/site-packages/flask/app.py\", line 2190, in wsgi_app\n    response = self.full_dispatch_request()\n  File \"/Users/user/Documents/Development/open-source-tools/GST-Verification-API/venv/lib/python3.13/site-packages/flask/app.py\", line 1487, in full_dispatch_request\n    return self.finalize_request(rv)\n           ~~~~~~~~~~~~~~~~~~~~~^^^^\n  File \"/Users/user/Documents/Development/open-source-tools/GST-Verification-API/venv/lib/python3.13/site-packages/flask/app.py\", line 1508, in finalize_request\n    response = self.process_response(response)\n  File \"/Users/user/Documents/Development/open-source-tools/GST-Verification-API/venv/lib/python3.13/site-packages/flask/app.py\", line 2002, in process_response\n    response = self.ensure_sync(func)(response)\n  File \"/Users/user/Documents/Development/open-source-tools/GST-Verification-API/logging_config.py\", line 546, in after_request\nTypeError: unsupported operand type(s) for -: 'datetime.datetime' and 'float'", "extra": {"taskName": null, "request_id": "1b4dd541-7a2c-4746-9ba3-c2a21ca00ceb"}}
{"timestamp": "2025-08-11T17:29:15.386130Z", "level": "ERROR", "logger": "app", "message": "Request finalizing failed with an error while handling an error", "module": "app", "function": "finalize_request", "line": 1515, "process_id": 50105, "thread_id": 123145602699264, "exception": "Traceback (most recent call last):\n  File \"/Users/user/Documents/Development/open-source-tools/GST-Verification-API/venv/lib/python3.13/site-packages/flask/app.py\", line 2190, in wsgi_app\n    response = self.full_dispatch_request()\n  File \"/Users/user/Documents/Development/open-source-tools/GST-Verification-API/venv/lib/python3.13/site-packages/flask/app.py\", line 1487, in full_dispatch_request\n    return self.finalize_request(rv)\n           ~~~~~~~~~~~~~~~~~~~~~^^^^\n  File \"/Users/user/Documents/Development/open-source-tools/GST-Verification-API/venv/lib/python3.13/site-packages/flask/app.py\", line 1508, in finalize_request\n    response = self.process_response(response)\n  File \"/Users/user/Documents/Development/open-source-tools/GST-Verification-API/venv/lib/python3.13/site-packages/flask/app.py\", line 2002, in process_response\n    response = self.ensure_sync(func)(response)\n  File \"/Users/user/Documents/Development/open-source-tools/GST-Verification-API/logging_config.py\", line 546, in after_request\nTypeError: unsupported operand type(s) for -: 'datetime.datetime' and 'float'\n\nDuring handling of the above exception, another exception occurred:\n\nTraceback (most recent call last):\n  File \"/Users/user/Documents/Development/open-source-tools/GST-Verification-API/venv/lib/python3.13/site-packages/flask/app.py\", line 1508, in finalize_request\n    response = self.process_response(response)\n  File \"/Users/user/Documents/Development/open-source-tools/GST-Verification-API/venv/lib/python3.13/site-packages/flask/app.py\", line 2002, in process_response\n    response = self.ensure_sync(func)(response)\n  File \"/Users/user/Documents/Development/open-source-tools/GST-Verification-API/logging_config.py\", line 546, in after_request\nTypeError: unsupported operand type(s) for -: 'datetime.datetime' and 'float'", "extra": {"taskName": null}}
{"timestamp": "2025-08-11T17:29:15.390678Z", "level": "ERROR", "logger": "gst_api.errors", "message": "Request failed with exception: unsupported operand type(s) for -: 'datetime.datetime' and 'float'", "module": "logging_config", "function": "teardown_request", "line": 563, "process_id": 50105, "thread_id": 123145602699264, "exception": "NoneType: None", "extra": {"taskName": null, "exception_type": "TypeError", "request_path": "/captcha", "request_method": "GET"}}
{"timestamp": "2025-08-11T17:29:17.882872Z", "level": "ERROR", "logger": "app", "message": "Exception on / [GET]", "module": "app", "function": "log_exception", "line": 1414, "process_id": 50105, "thread_id": 123145653067776, "exception": "Traceback (most recent call last):\n  File \"/Users/user/Documents/Development/open-source-tools/GST-Verification-API/venv/lib/python3.13/site-packages/flask/app.py\", line 2190, in wsgi_app\n    response = self.full_dispatch_request()\n  File \"/Users/user/Documents/Development/open-source-tools/GST-Verification-API/venv/lib/python3.13/site-packages/flask/app.py\", line 1487, in full_dispatch_request\n    return self.finalize_request(rv)\n           ~~~~~~~~~~~~~~~~~~~~~^^^^\n  File \"/Users/user/Documents/Development/open-source-tools/GST-Verification-API/venv/lib/python3.13/site-packages/flask/app.py\", line 1508, in finalize_request\n    response = self.process_response(response)\n  File \"/Users/user/Documents/Development/open-source-tools/GST-Verification-API/venv/lib/python3.13/site-packages/flask/app.py\", line 2002, in process_response\n    response = self.ensure_sync(func)(response)\n  File \"/Users/user/Documents/Development/open-source-tools/GST-Verification-API/logging_config.py\", line 546, in after_request\nTypeError: unsupported operand type(s) for -: 'datetime.datetime' and 'float'", "extra": {"taskName": null}}
{"timestamp": "2025-08-11T17:29:17.887335Z", "level": "ERROR", "logger": "gst_api", "message": "Internal server error: 500 Internal Server Error: The server encountered an internal error and was unable to complete your request. Either the server is overloaded or there is an error in the application.", "module": "app", "function": "internal_error", "line": 254, "process_id": 50105, "thread_id": 123145653067776, "exception": "Traceback (most recent call last):\n  File \"/Users/user/Documents/Development/open-source-tools/GST-Verification-API/venv/lib/python3.13/site-packages/flask/app.py\", line 2190, in wsgi_app\n    response = self.full_dispatch_request()\n  File \"/Users/user/Documents/Development/open-source-tools/GST-Verification-API/venv/lib/python3.13/site-packages/flask/app.py\", line 1487, in full_dispatch_request\n    return self.finalize_request(rv)\n           ~~~~~~~~~~~~~~~~~~~~~^^^^\n  File \"/Users/user/Documents/Development/open-source-tools/GST-Verification-API/venv/lib/python3.13/site-packages/flask/app.py\", line 1508, in finalize_request\n    response = self.process_response(response)\n  File \"/Users/user/Documents/Development/open-source-tools/GST-Verification-API/venv/lib/python3.13/site-packages/flask/app.py\", line 2002, in process_response\n    response = self.ensure_sync(func)(response)\n  File \"/Users/user/Documents/Development/open-source-tools/GST-Verification-API/logging_config.py\", line 546, in after_request\nTypeError: unsupported operand type(s) for -: 'datetime.datetime' and 'float'", "extra": {"taskName": null, "request_id": "be965c54-072d-433c-af26-b4a1d68bf282"}}
{"timestamp": "2025-08-11T17:29:17.891224Z", "level": "ERROR", "logger": "app", "message": "Request finalizing failed with an error while handling an error", "module": "app", "function": "finalize_request", "line": 1515, "process_id": 50105, "thread_id": 123145653067776, "exception": "Traceback (most recent call last):\n  File \"/Users/user/Documents/Development/open-source-tools/GST-Verification-API/venv/lib/python3.13/site-packages/flask/app.py\", line 2190, in wsgi_app\n    response = self.full_dispatch_request()\n  File \"/Users/user/Documents/Development/open-source-tools/GST-Verification-API/venv/lib/python3.13/site-packages/flask/app.py\", line 1487, in full_dispatch_request\n    return self.finalize_request(rv)\n           ~~~~~~~~~~~~~~~~~~~~~^^^^\n  File \"/Users/user/Documents/Development/open-source-tools/GST-Verification-API/venv/lib/python3.13/site-packages/flask/app.py\", line 1508, in finalize_request\n    response = self.process_response(response)\n  File \"/Users/user/Documents/Development/open-source-tools/GST-Verification-API/venv/lib/python3.13/site-packages/flask/app.py\", line 2002, in process_response\n    response = self.ensure_sync(func)(response)\n  File \"/Users/user/Documents/Development/open-source-tools/GST-Verification-API/logging_config.py\", line 546, in after_request\nTypeError: unsupported operand type(s) for -: 'datetime.datetime' and 'float'\n\nDuring handling of the above exception, another exception occurred:\n\nTraceback (most recent call last):\n  File \"/Users/user/Documents/Development/open-source-tools/GST-Verification-API/venv/lib/python3.13/site-packages/flask/app.py\", line 1508, in finalize_request\n    response = self.process_response(response)\n  File \"/Users/user/Documents/Development/open-source-tools/GST-Verification-API/venv/lib/python3.13/site-packages/flask/app.py\", line 2002, in process_response\n    response = self.ensure_sync(func)(response)\n  File \"/Users/user/Documents/Development/open-source-tools/GST-Verification-API/logging_config.py\", line 546, in after_request\nTypeError: unsupported operand type(s) for -: 'datetime.datetime' and 'float'", "extra": {"taskName": null}}
{"timestamp": "2025-08-11T17:29:17.897828Z", "level": "ERROR", "logger": "gst_api.errors", "message": "Request failed with exception: unsupported operand type(s) for -: 'datetime.datetime' and 'float'", "module": "logging_config", "function": "teardown_request", "line": 563, "process_id": 50105, "thread_id": 123145653067776, "exception": "NoneType: None", "extra": {"taskName": null, "exception_type": "TypeError", "request_path": "/", "request_method": "GET"}}
{"timestamp": "2025-08-11T17:31:35.244110Z", "level": "ERROR", "logger": "app", "message": "Exception on / [GET]", "module": "app", "function": "log_exception", "line": 1414, "process_id": 50105, "thread_id": 123145669857280, "exception": "Traceback (most recent call last):\n  File \"/Users/user/Documents/Development/open-source-tools/GST-Verification-API/venv/lib/python3.13/site-packages/flask/app.py\", line 2190, in wsgi_app\n    response = self.full_dispatch_request()\n  File \"/Users/user/Documents/Development/open-source-tools/GST-Verification-API/venv/lib/python3.13/site-packages/flask/app.py\", line 1487, in full_dispatch_request\n    return self.finalize_request(rv)\n           ~~~~~~~~~~~~~~~~~~~~~^^^^\n  File \"/Users/user/Documents/Development/open-source-tools/GST-Verification-API/venv/lib/python3.13/site-packages/flask/app.py\", line 1508, in finalize_request\n    response = self.process_response(response)\n  File \"/Users/user/Documents/Development/open-source-tools/GST-Verification-API/venv/lib/python3.13/site-packages/flask/app.py\", line 2002, in process_response\n    response = self.ensure_sync(func)(response)\n  File \"/Users/user/Documents/Development/open-source-tools/GST-Verification-API/logging_config.py\", line 546, in after_request\nTypeError: unsupported operand type(s) for -: 'datetime.datetime' and 'float'", "extra": {"taskName": null}}
{"timestamp": "2025-08-11T17:31:35.248517Z", "level": "ERROR", "logger": "gst_api", "message": "Internal server error: 500 Internal Server Error: The server encountered an internal error and was unable to complete your request. Either the server is overloaded or there is an error in the application.", "module": "app", "function": "internal_error", "line": 254, "process_id": 50105, "thread_id": 123145669857280, "exception": "Traceback (most recent call last):\n  File \"/Users/user/Documents/Development/open-source-tools/GST-Verification-API/venv/lib/python3.13/site-packages/flask/app.py\", line 2190, in wsgi_app\n    response = self.full_dispatch_request()\n  File \"/Users/user/Documents/Development/open-source-tools/GST-Verification-API/venv/lib/python3.13/site-packages/flask/app.py\", line 1487, in full_dispatch_request\n    return self.finalize_request(rv)\n           ~~~~~~~~~~~~~~~~~~~~~^^^^\n  File \"/Users/user/Documents/Development/open-source-tools/GST-Verification-API/venv/lib/python3.13/site-packages/flask/app.py\", line 1508, in finalize_request\n    response = self.process_response(response)\n  File \"/Users/user/Documents/Development/open-source-tools/GST-Verification-API/venv/lib/python3.13/site-packages/flask/app.py\", line 2002, in process_response\n    response = self.ensure_sync(func)(response)\n  File \"/Users/user/Documents/Development/open-source-tools/GST-Verification-API/logging_config.py\", line 546, in after_request\nTypeError: unsupported operand type(s) for -: 'datetime.datetime' and 'float'", "extra": {"taskName": null, "request_id": "b60d44bf-0218-4b5f-a56b-189d5e7fcc38"}}
{"timestamp": "2025-08-11T17:31:35.252971Z", "level": "ERROR", "logger": "app", "message": "Request finalizing failed with an error while handling an error", "module": "app", "function": "finalize_request", "line": 1515, "process_id": 50105, "thread_id": 123145669857280, "exception": "Traceback (most recent call last):\n  File \"/Users/user/Documents/Development/open-source-tools/GST-Verification-API/venv/lib/python3.13/site-packages/flask/app.py\", line 2190, in wsgi_app\n    response = self.full_dispatch_request()\n  File \"/Users/user/Documents/Development/open-source-tools/GST-Verification-API/venv/lib/python3.13/site-packages/flask/app.py\", line 1487, in full_dispatch_request\n    return self.finalize_request(rv)\n           ~~~~~~~~~~~~~~~~~~~~~^^^^\n  File \"/Users/user/Documents/Development/open-source-tools/GST-Verification-API/venv/lib/python3.13/site-packages/flask/app.py\", line 1508, in finalize_request\n    response = self.process_response(response)\n  File \"/Users/user/Documents/Development/open-source-tools/GST-Verification-API/venv/lib/python3.13/site-packages/flask/app.py\", line 2002, in process_response\n    response = self.ensure_sync(func)(response)\n  File \"/Users/user/Documents/Development/open-source-tools/GST-Verification-API/logging_config.py\", line 546, in after_request\nTypeError: unsupported operand type(s) for -: 'datetime.datetime' and 'float'\n\nDuring handling of the above exception, another exception occurred:\n\nTraceback (most recent call last):\n  File \"/Users/user/Documents/Development/open-source-tools/GST-Verification-API/venv/lib/python3.13/site-packages/flask/app.py\", line 1508, in finalize_request\n    response = self.process_response(response)\n  File \"/Users/user/Documents/Development/open-source-tools/GST-Verification-API/venv/lib/python3.13/site-packages/flask/app.py\", line 2002, in process_response\n    response = self.ensure_sync(func)(response)\n  File \"/Users/user/Documents/Development/open-source-tools/GST-Verification-API/logging_config.py\", line 546, in after_request\nTypeError: unsupported operand type(s) for -: 'datetime.datetime' and 'float'", "extra": {"taskName": null}}
{"timestamp": "2025-08-11T17:31:35.256947Z", "level": "ERROR", "logger": "gst_api.errors", "message": "Request failed with exception: unsupported operand type(s) for -: 'datetime.datetime' and 'float'", "module": "logging_config", "function": "teardown_request", "line": 563, "process_id": 50105, "thread_id": 123145669857280, "exception": "NoneType: None", "extra": {"taskName": null, "exception_type": "TypeError", "request_path": "/", "request_method": "GET"}}
{"timestamp": "2025-08-11T17:33:18.662314Z", "level": "ERROR", "logger": "gst_api", "message": "Health check failed: 'HealthChecker' object has no attribute 'check_health'", "module": "app", "function": "health_check", "line": 560, "process_id": 58287, "thread_id": 123145535557632, "extra": {"taskName": null}}
{"timestamp": "2025-08-11T17:36:58.214679Z", "level": "ERROR", "logger": "gst_api", "message": "Health check failed: 'HealthChecker' object has no attribute 'check_health'", "module": "app", "function": "health_check", "line": 560, "process_id": 63123, "thread_id": 123145369563136, "extra": {"taskName": null}}
{"timestamp": "2025-08-11T17:42:15.198014Z", "level": "ERROR", "logger": "gst_api", "message": "Invalid JSON response from GST portal: Expecting value: line 1 column 1 (char 0)", "module": "app", "function": "get_gst_details", "line": 779, "process_id": 63123, "thread_id": 123145420468224, "extra": {"taskName": null}}
{"timestamp": "2025-08-11T17:42:54.758950Z", "level": "ERROR", "logger": "gst_api", "message": "Invalid JSON response from GST portal: Expecting value: line 1 column 1 (char 0)", "module": "app", "function": "get_gst_details", "line": 779, "process_id": 63123, "thread_id": 123145420468224, "extra": {"taskName": null}}
{"timestamp": "2025-08-11T17:43:29.788462Z", "level": "ERROR", "logger": "gst_api", "message": "Invalid JSON response from GST portal: Expecting value: line 1 column 1 (char 0)", "module": "app", "function": "get_gst_details", "line": 779, "process_id": 63123, "thread_id": 123145420468224, "extra": {"taskName": null}}
{"timestamp": "2025-08-11T17:44:58.326982Z", "level": "ERROR", "logger": "gst_api", "message": "Invalid JSON response from GST portal: Expecting value: line 1 column 1 (char 0)", "module": "app", "function": "get_gst_details", "line": 779, "process_id": 63123, "thread_id": 123145420468224, "extra": {"taskName": null}}
{"timestamp": "2025-08-11T17:46:25.219349Z", "level": "ERROR", "logger": "gst_api", "message": "Invalid JSON response from GST portal: Expecting value: line 1 column 1 (char 0)", "module": "app", "function": "get_gst_details", "line": 779, "process_id": 63123, "thread_id": 123145420468224, "extra": {"taskName": null}}
